<?xml version="1.0" ?>
<!-- =================================================================================== -->
<!-- |    This document was autogenerated by xacro from tb_full.urdf.xacro             | -->
<!-- |    EDITING THIS FILE BY HAND IS NOT RECOMMENDED                                 | -->
<!-- =================================================================================== -->
<robot name="fishbot">
  <!-- Create 3 base definition-->
  <link name="base_link">
    <visual>
      <origin rpy="0 0 1.5707963267948966" xyz="0 0 0.039200000000000006"/>
      <geometry>
        <mesh filename="package://irobot_create_description/meshes/body_visual.dae"/>
      </geometry>
    </visual>
    <collision name="create3_base_collision">
      <origin rpy="0 0 1.5707963267948966" xyz="0 0 0.04920000000000001"/>
      <geometry>
        <cylinder length="0.06" radius="0.16399999999999998"/>
      </geometry>
    </collision>
    <inertial>
      <origin xyz="0.0 0 0.0742"/>
      <mass value="2.3"/>
      <inertia ixx="0.016155199999999998" ixy="0.0" ixz="0.0" iyy="0.016155199999999998" iyz="0.0" izz="0.03093039999999999"/>
    </inertial>
  </link>
  <joint name="bumper_joint" type="fixed">
    <parent link="base_link"/>
    <child link="bumper"/>
    <origin xyz="0 0 0.039200000000000006"/>
  </joint>
  <link name="bumper">
    <visual>
      <geometry>
        <mesh filename="package://irobot_create_description/meshes/bumper_visual.dae"/>
      </geometry>
    </visual>
    <collision>
      <geometry>
        <mesh filename="package://irobot_create_description/meshes/bumper_collision.dae"/>
      </geometry>
    </collision>
    <inertial>
      <origin xyz="0.08 0 0.02"/>
      <mass value="0.1"/>
      <inertia ixx="0.0013483753405" ixy="0.0000000454352" ixz="0.0000014434849" iyy="0.0002521736852" iyz="-0.0000000006721" izz="0.0015442525386"/>
    </inertial>
  </link>
  <gazebo reference="bumper">
    <mu1>0.1</mu1>
    <mu2>0.1</mu2>
    <maxVel>0.01</maxVel>
    <minDepth>0.001</minDepth>
    <maxContacts>10</maxContacts>
    <material>Gazebo/DarkGrey</material>
    <sensor name="bumper_contact_sensor" type="contact">
      <always_on>true</always_on>
      <update_rate>62.0</update_rate>
      <contact>
        <collision>bumper_collision</collision>
      </contact>
      <plugin filename="libgazebo_ros_create_bumper.so" name="bumper_plugin">
        <ros>
          <namespace></namespace>
          <remapping>~/out:=_internal/bumper/event</remapping>
        </ros>
      </plugin>
    </sensor>
  </gazebo>
  <gazebo reference="bumper_joint">
    <preserveFixedJoint>true</preserveFixedJoint>
  </gazebo>
  <joint name="bump_front_center_joint" type="fixed">
    <parent link="base_link"/>
    <child link="bump_front_center"/>
    <origin rpy="0 0 0" xyz="0.175 0 0.039"/>
  </joint>
  <link name="bump_front_center"/>
  <joint name="bump_front_left_joint" type="fixed">
    <parent link="base_link"/>
    <child link="bump_front_left"/>
    <origin rpy="0 0 0.5235985" xyz="0.02345 -0.0875 0.025"/>
  </joint>
  <link name="bump_front_left"/>
  <joint name="bump_front_right_joint" type="fixed">
    <parent link="base_link"/>
    <child link="bump_front_right"/>
    <origin rpy="0 0 -0.5235985" xyz="0.02345 0.0875 0.025"/>
  </joint>
  <link name="bump_front_right"/>
  <joint name="bump_left_joint" type="fixed">
    <parent link="base_link"/>
    <child link="bump_left"/>
    <origin rpy="0 0 1.047193" xyz="0.0875 -0.15155 0.025"/>
  </joint>
  <link name="bump_left"/>
  <joint name="bump_right_joint" type="fixed">
    <parent link="base_link"/>
    <child link="bump_right"/>
    <origin rpy="0 0 -1.047193" xyz="0.0875 0.15155 0.025"/>
  </joint>
  <link name="bump_right"/>
  <joint name="wheel_drop_left_joint" type="prismatic">
    <parent link="base_link"/>
    <child link="wheel_drop_left"/>
    <origin rpy="-1.5707963267948966 0 0" xyz="0 0.1165 0.04020000000000001"/>
    <axis xyz="0 1 0"/>
    <limit effort="0" lower="0" upper="0.03" velocity="0"/>
    <!-- Damping is big enough to not make the body oscillate too much when it's lifted up -->
    <dynamics damping="50" friction="0.1"/>
  </joint>
  <!-- Gazebo parameters to simulate a spring -->
  <gazebo reference="wheel_drop_left_joint">
    <provideFeedback>false</provideFeedback>
    <implicitSpringDamper>true</implicitSpringDamper>
    <!-- This value should be high enough so that the wheeldrop can
          retract with the robot's weight (mass * gravity) -->
    <springStiffness>400</springStiffness>
    <springReference>0.03</springReference>
  </gazebo>
  <link name="wheel_drop_left">
    <inertial>
      <mass value="0.05"/>
      <origin xyz="0 0 0"/>
      <inertia ixx="2.0833333333333336e-05" ixy="0.0" ixz="0.0" iyy="2.0833333333333336e-05" iyz="0.0" izz="2.0833333333333336e-05"/>
    </inertial>
  </link>
  <gazebo>
    <plugin filename="libgazebo_ros_create_wheel_drop.so" name="wheel_drop_left_plugin">
      <ros>
        <namespace></namespace>
        <remapping>~/out:=_internal/wheel_drop/left_wheel/event</remapping>
      </ros>
      <update_rate>62</update_rate>
      <detection_threshold>0.03</detection_threshold>
      <joint_name>wheel_drop_left_joint</joint_name>
      <frame_id>wheel_drop_left</frame_id>
    </plugin>
  </gazebo>
  <joint name="left_wheel_joint" type="continuous">
    <parent link="wheel_drop_left"/>
    <child link="left_wheel"/>
    <origin rpy="0 0 0" xyz="0 0 0"/>
    <axis xyz="0 0 1"/>
  </joint>
  <link name="left_wheel">
    <visual>
      <geometry>
        <cylinder length="0.015" radius="0.035750000000000004"/>
      </geometry>
      <!-- Give black color to wheels in Rviz -->
      <material name="black">
        <color rgba="0.1 0.1 0.1 1"/>
      </material>
    </visual>
    <collision>
      <geometry>
        <cylinder length="0.015" radius="0.035750000000000004"/>
      </geometry>
    </collision>
    <inertial>
      <origin xyz="0 0 0"/>
      <mass value="0.2"/>
      <inertia ixx="6.765312500000001e-05" ixy="0.0" ixz="0.0" iyy="6.765312500000001e-05" iyz="0.0" izz="0.00012780625000000003"/>
    </inertial>
  </link>
  <gazebo reference="left_wheel">
    <mu1>1.0</mu1>
    <mu2>1.0</mu2>
    <kp>1000000.0</kp>
    <kd>100.0</kd>
    <minDepth>0.0001</minDepth>
    <maxVel>1.0</maxVel>
    <material>Gazebo/DarkGrey</material>
  </gazebo>
  <ros2_control name="left_wheel_controller" type="system">
    <hardware>
      <plugin>gazebo_ros2_control/GazeboSystem</plugin>
    </hardware>
    <joint name="left_wheel_joint">
      <state_interface name="velocity"/>
      <state_interface name="position"/>
      <command_interface name="velocity"/>
    </joint>
  </ros2_control>
  <joint name="wheel_drop_right_joint" type="prismatic">
    <parent link="base_link"/>
    <child link="wheel_drop_right"/>
    <origin rpy="-1.5707963267948966 0 0" xyz="0 -0.1165 0.04020000000000001"/>
    <axis xyz="0 1 0"/>
    <limit effort="0" lower="0" upper="0.03" velocity="0"/>
    <!-- Damping is big enough to not make the body oscillate too much when it's lifted up -->
    <dynamics damping="50" friction="0.1"/>
  </joint>
  <!-- Gazebo parameters to simulate a spring -->
  <gazebo reference="wheel_drop_right_joint">
    <provideFeedback>false</provideFeedback>
    <implicitSpringDamper>true</implicitSpringDamper>
    <!-- This value should be high enough so that the wheeldrop can
          retract with the robot's weight (mass * gravity) -->
    <springStiffness>400</springStiffness>
    <springReference>0.03</springReference>
  </gazebo>
  <link name="wheel_drop_right">
    <inertial>
      <mass value="0.05"/>
      <origin xyz="0 0 0"/>
      <inertia ixx="2.0833333333333336e-05" ixy="0.0" ixz="0.0" iyy="2.0833333333333336e-05" iyz="0.0" izz="2.0833333333333336e-05"/>
    </inertial>
  </link>
  <gazebo>
    <plugin filename="libgazebo_ros_create_wheel_drop.so" name="wheel_drop_right_plugin">
      <ros>
        <namespace></namespace>
        <remapping>~/out:=_internal/wheel_drop/right_wheel/event</remapping>
      </ros>
      <update_rate>62</update_rate>
      <detection_threshold>0.03</detection_threshold>
      <joint_name>wheel_drop_right_joint</joint_name>
      <frame_id>wheel_drop_right</frame_id>
    </plugin>
  </gazebo>
  <joint name="right_wheel_joint" type="continuous">
    <parent link="wheel_drop_right"/>
    <child link="right_wheel"/>
    <origin rpy="0 0 0" xyz="0 0 0"/>
    <axis xyz="0 0 1"/>
  </joint>
  <link name="right_wheel">
    <visual>
      <geometry>
        <cylinder length="0.015" radius="0.035750000000000004"/>
      </geometry>
      <!-- Give black color to wheels in Rviz -->
      <material name="black">
        <color rgba="0.1 0.1 0.1 1"/>
      </material>
    </visual>
    <collision>
      <geometry>
        <cylinder length="0.015" radius="0.035750000000000004"/>
      </geometry>
    </collision>
    <inertial>
      <origin xyz="0 0 0"/>
      <mass value="0.2"/>
      <inertia ixx="6.765312500000001e-05" ixy="0.0" ixz="0.0" iyy="6.765312500000001e-05" iyz="0.0" izz="0.00012780625000000003"/>
    </inertial>
  </link>
  <gazebo reference="right_wheel">
    <mu1>1.0</mu1>
    <mu2>1.0</mu2>
    <kp>1000000.0</kp>
    <kd>100.0</kd>
    <minDepth>0.0001</minDepth>
    <maxVel>1.0</maxVel>
    <material>Gazebo/DarkGrey</material>
  </gazebo>
  <ros2_control name="right_wheel_controller" type="system">
    <hardware>
      <plugin>gazebo_ros2_control/GazeboSystem</plugin>
    </hardware>
    <joint name="right_wheel_joint">
      <state_interface name="velocity"/>
      <state_interface name="position"/>
      <command_interface name="velocity"/>
    </joint>
  </ros2_control>
  <joint name="front_caster_joint" type="fixed">
    <parent link="base_link"/>
    <child link="front_caster_link"/>
    <origin rpy="-1.5707963267948966 0 0" xyz="0.125 0 0.012200000000000003"/>
  </joint>
  <link name="front_caster_link">
    <visual>
      <geometry>
        <sphere radius="0.01"/>
      </geometry>
      <!-- Give black color to caster in Rviz -->
      <material name="black">
        <color rgba="0.1 0.1 0.1 1"/>
      </material>
    </visual>
    <collision>
      <geometry>
        <sphere radius="0.01"/>
      </geometry>
    </collision>
    <inertial>
      <mass value="0.01"/>
      <inertia ixx="4.0000000000000003e-07" ixy="0.0" ixz="0.0" iyy="4.0000000000000003e-07" iyz="0.0" izz="4.0000000000000003e-07"/>
    </inertial>
  </link>
  <gazebo reference="front_caster_joint">
    <preserveFixedJoint>true</preserveFixedJoint>
  </gazebo>
  <gazebo reference="front_caster_link">
    <material>Gazebo/DarkGrey</material>
    <mu1>0.1</mu1>
    <mu2>0.1</mu2>
    <kp>1000000.0</kp>
    <kd>1.0</kd>
  </gazebo>
  <joint name="imu_joint" type="fixed">
    <origin xyz="0.050613 0.043673 0.0844"/>
    <parent link="base_link"/>
    <child link="imu_link"/>
  </joint>
  <link name="imu_link">
    <inertial>
      <mass value="0.01"/>
      <origin xyz="0 0 0"/>
      <inertia ixx="1.6666666666666668e-07" ixy="0.0" ixz="0.0" iyy="1.6666666666666668e-07" iyz="0.0" izz="1.6666666666666668e-07"/>
    </inertial>
  </link>
  <gazebo reference="imu_link">
    <sensor name="imu" type="imu">
      <always_on>true</always_on>
      <update_rate>62</update_rate>
      <imu>
        <angular_velocity>
          <x>
            <noise type="gaussian">
              <mean>0.0</mean>
              <stddev>0.0</stddev>
            </noise>
          </x>
          <y>
            <noise type="gaussian">
              <mean>0.0</mean>
              <stddev>0.0</stddev>
            </noise>
          </y>
          <z>
            <noise type="gaussian">
              <mean>0.0</mean>
              <stddev>0.0</stddev>
            </noise>
          </z>
        </angular_velocity>
        <linear_acceleration>
          <x>
            <noise type="gaussian">
              <mean>0.0</mean>
              <stddev>0.0</stddev>
            </noise>
          </x>
          <y>
            <noise type="gaussian">
              <mean>0.0</mean>
              <stddev>0.0</stddev>
            </noise>
          </y>
          <z>
            <noise type="gaussian">
              <mean>0.0</mean>
              <stddev>0.0</stddev>
            </noise>
          </z>
        </linear_acceleration>
      </imu>
      <plugin filename="libgazebo_ros_create_imu.so" name="imu_plugin">
        <ros>
          <namespace></namespace>
          <remapping>~/out:=imu</remapping>
        </ros>
      </plugin>
    </sensor>
  </gazebo>
  <gazebo reference="imu_joint">
    <preserveFixedJoint>true</preserveFixedJoint>
  </gazebo>
  <gazebo>
    <plugin filename="libgazebo_ros2_control.so" name="gazebo_ros2_control">
      <parameters>/opt/ros/humble/share/irobot_create_control/config/control.yaml</parameters>
      <ros>
        <remapping>~/odom:=odom</remapping>
        <remapping>/tf:=tf</remapping>
        <remapping>/tf_static:=tf_static</remapping>
        <remapping>/diagnostics:=diagnostics</remapping>
        <namespace></namespace>
      </ros>
    </plugin>
  </gazebo>
  <joint name="mouse_joint" type="fixed">
    <origin rpy="0 0 -0.7853981633974483" xyz="0.1015 0.087 0.009200000000000007"/>
    <parent link="base_link"/>
    <child link="mouse"/>
  </joint>
  <link name="mouse">
    <inertial>
      <mass value="0.01"/>
      <origin xyz="0 0 0"/>
      <inertia ixx="1.6666666666666668e-07" ixy="0.0" ixz="0.0" iyy="1.6666666666666668e-07" iyz="0.0" izz="1.6666666666666668e-07"/>
    </inertial>
  </link>
  <gazebo>
    <plugin filename="libgazebo_ros_create_optical_mouse.so" name="mouse_plugin">
      <ros>
        <namespace></namespace>
        <remapping>~/out:=mouse</remapping>
      </ros>
      <update_rate>62</update_rate>
      <link_name>mouse</link_name>
    </plugin>
  </gazebo>
  <gazebo reference="mouse_joint">
    <preserveFixedJoint>true</preserveFixedJoint>
  </gazebo>
  <joint name="cliff_side_left_joint" type="fixed">
    <origin rpy="0 1.3962634015954636 2.921681167838508" xyz="0.06 0.145 0.01920000000000001"/>
    <parent link="base_link"/>
    <child link="cliff_side_left"/>
  </joint>
  <link name="cliff_side_left">
    <inertial>
      <mass value="0.01"/>
      <origin xyz="0 0 0"/>
      <inertia ixx="1.6666666666666668e-07" ixy="0.0" ixz="0.0" iyy="1.6666666666666668e-07" iyz="0.0" izz="1.6666666666666668e-07"/>
    </inertial>
  </link>
  <gazebo reference="cliff_side_left">
    <sensor name="cliff_side_left" type="ray">
      <update_rate>62</update_rate>
      <visualize>False</visualize>
      <always_on>true</always_on>
      <ray>
        <scan>
          <horizontal>
            <samples>1.0</samples>
            <resolution>1.0</resolution>
            <min_angle>-0.04363323129985824</min_angle>
            <max_angle>0.04363323129985824</max_angle>
          </horizontal>
          <vertical>
            <samples>1</samples>
            <resolution>1</resolution>
            <min_angle>0</min_angle>
            <max_angle>0</max_angle>
          </vertical>
        </scan>
        <range>
          <min>0.0001</min>
          <max>0.15</max>
          <resolution>1.0</resolution>
        </range>
      </ray>
      <!-- Noise is currently disabled -->
      <noise>
        <type>gaussian</type>
        <mean>0.0</mean>
        <stddev>0.0</stddev>
      </noise>
      <plugin filename="libgazebo_ros_create_cliff_sensor.so" name="cliff_side_left">
        <ros>
          <namespace></namespace>
          <remapping>~/out:=_internal/cliff_side_left/event</remapping>
        </ros>
        <detection_threshold>0.08</detection_threshold>
        <frame_id>cliff_side_left</frame_id>
      </plugin>
    </sensor>
  </gazebo>
  <joint name="cliff_side_right_joint" type="fixed">
    <origin rpy="0 1.3962634015954636 -2.921681167838508" xyz="0.06 -0.145 0.01920000000000001"/>
    <parent link="base_link"/>
    <child link="cliff_side_right"/>
  </joint>
  <link name="cliff_side_right">
    <inertial>
      <mass value="0.01"/>
      <origin xyz="0 0 0"/>
      <inertia ixx="1.6666666666666668e-07" ixy="0.0" ixz="0.0" iyy="1.6666666666666668e-07" iyz="0.0" izz="1.6666666666666668e-07"/>
    </inertial>
  </link>
  <gazebo reference="cliff_side_right">
    <sensor name="cliff_side_right" type="ray">
      <update_rate>62</update_rate>
      <visualize>False</visualize>
      <always_on>true</always_on>
      <ray>
        <scan>
          <horizontal>
            <samples>1.0</samples>
            <resolution>1.0</resolution>
            <min_angle>-0.04363323129985824</min_angle>
            <max_angle>0.04363323129985824</max_angle>
          </horizontal>
          <vertical>
            <samples>1</samples>
            <resolution>1</resolution>
            <min_angle>0</min_angle>
            <max_angle>0</max_angle>
          </vertical>
        </scan>
        <range>
          <min>0.0001</min>
          <max>0.15</max>
          <resolution>1.0</resolution>
        </range>
      </ray>
      <!-- Noise is currently disabled -->
      <noise>
        <type>gaussian</type>
        <mean>0.0</mean>
        <stddev>0.0</stddev>
      </noise>
      <plugin filename="libgazebo_ros_create_cliff_sensor.so" name="cliff_side_right">
        <ros>
          <namespace></namespace>
          <remapping>~/out:=_internal/cliff_side_right/event</remapping>
        </ros>
        <detection_threshold>0.08</detection_threshold>
        <frame_id>cliff_side_right</frame_id>
      </plugin>
    </sensor>
  </gazebo>
  <joint name="cliff_front_left_joint" type="fixed">
    <origin rpy="0 1.3962634015954636 1.1397000015522971" xyz="0.16 0.045 0.01920000000000001"/>
    <parent link="base_link"/>
    <child link="cliff_front_left"/>
  </joint>
  <link name="cliff_front_left">
    <inertial>
      <mass value="0.01"/>
      <origin xyz="0 0 0"/>
      <inertia ixx="1.6666666666666668e-07" ixy="0.0" ixz="0.0" iyy="1.6666666666666668e-07" iyz="0.0" izz="1.6666666666666668e-07"/>
    </inertial>
  </link>
  <gazebo reference="cliff_front_left">
    <sensor name="cliff_front_left" type="ray">
      <update_rate>62</update_rate>
      <visualize>False</visualize>
      <always_on>true</always_on>
      <ray>
        <scan>
          <horizontal>
            <samples>1.0</samples>
            <resolution>1.0</resolution>
            <min_angle>-0.04363323129985824</min_angle>
            <max_angle>0.04363323129985824</max_angle>
          </horizontal>
          <vertical>
            <samples>1</samples>
            <resolution>1</resolution>
            <min_angle>0</min_angle>
            <max_angle>0</max_angle>
          </vertical>
        </scan>
        <range>
          <min>0.0001</min>
          <max>0.15</max>
          <resolution>1.0</resolution>
        </range>
      </ray>
      <!-- Noise is currently disabled -->
      <noise>
        <type>gaussian</type>
        <mean>0.0</mean>
        <stddev>0.0</stddev>
      </noise>
      <plugin filename="libgazebo_ros_create_cliff_sensor.so" name="cliff_front_left">
        <ros>
          <namespace></namespace>
          <remapping>~/out:=_internal/cliff_front_left/event</remapping>
        </ros>
        <detection_threshold>0.08</detection_threshold>
        <frame_id>cliff_front_left</frame_id>
      </plugin>
    </sensor>
  </gazebo>
  <joint name="cliff_front_right_joint" type="fixed">
    <origin rpy="0 1.3962634015954636 -1.1397000015522971" xyz="0.16 -0.045 0.01920000000000001"/>
    <parent link="base_link"/>
    <child link="cliff_front_right"/>
  </joint>
  <link name="cliff_front_right">
    <inertial>
      <mass value="0.01"/>
      <origin xyz="0 0 0"/>
      <inertia ixx="1.6666666666666668e-07" ixy="0.0" ixz="0.0" iyy="1.6666666666666668e-07" iyz="0.0" izz="1.6666666666666668e-07"/>
    </inertial>
  </link>
  <gazebo reference="cliff_front_right">
    <sensor name="cliff_front_right" type="ray">
      <update_rate>62</update_rate>
      <visualize>False</visualize>
      <always_on>true</always_on>
      <ray>
        <scan>
          <horizontal>
            <samples>1.0</samples>
            <resolution>1.0</resolution>
            <min_angle>-0.04363323129985824</min_angle>
            <max_angle>0.04363323129985824</max_angle>
          </horizontal>
          <vertical>
            <samples>1</samples>
            <resolution>1</resolution>
            <min_angle>0</min_angle>
            <max_angle>0</max_angle>
          </vertical>
        </scan>
        <range>
          <min>0.0001</min>
          <max>0.15</max>
          <resolution>1.0</resolution>
        </range>
      </ray>
      <!-- Noise is currently disabled -->
      <noise>
        <type>gaussian</type>
        <mean>0.0</mean>
        <stddev>0.0</stddev>
      </noise>
      <plugin filename="libgazebo_ros_create_cliff_sensor.so" name="cliff_front_right">
        <ros>
          <namespace></namespace>
          <remapping>~/out:=_internal/cliff_front_right/event</remapping>
        </ros>
        <detection_threshold>0.08</detection_threshold>
        <frame_id>cliff_front_right</frame_id>
      </plugin>
    </sensor>
  </gazebo>
  <joint name="ir_intensity_front_center_left_joint" type="fixed">
    <origin xyz="0.1540 0 0.05720000000000001"/>
    <parent link="base_link"/>
    <child link="ir_intensity_front_center_left"/>
  </joint>
  <link name="ir_intensity_front_center_left">
    <inertial>
      <mass value="0.01"/>
      <origin xyz="0 0 0"/>
      <inertia ixx="1.6666666666666668e-07" ixy="0.0" ixz="0.0" iyy="1.6666666666666668e-07" iyz="0.0" izz="1.6666666666666668e-07"/>
    </inertial>
  </link>
  <gazebo reference="ir_intensity_front_center_left_joint">
    <preserveFixedJoint>true</preserveFixedJoint>
  </gazebo>
  <gazebo reference="ir_intensity_front_center_left">
    <sensor name="ir_intensity_front_center_left" type="ray">
      <update_rate>62.0</update_rate>
      <visualize>False</visualize>
      <always_on>true</always_on>
      <ray>
        <scan>
          <horizontal>
            <samples>5</samples>
            <resolution>1.0</resolution>
            <min_angle>-0.08726646259971647</min_angle>
            <max_angle>0.08726646259971647</max_angle>
          </horizontal>
          <vertical>
            <samples>5</samples>
            <resolution>1.0</resolution>
            <min_angle>-0.08726646259971647</min_angle>
            <max_angle>0.08726646259971647</max_angle>
          </vertical>
        </scan>
        <range>
          <min>0.025</min>
          <max>0.2</max>
          <resolution>1.0</resolution>
        </range>
      </ray>
      <!-- Noise is currently disabled -->
      <noise>
        <type>gaussian</type>
        <mean>0.0</mean>
        <stddev>0.0</stddev>
      </noise>
      <plugin filename="libgazebo_ros_create_ir_intensity_sensor.so" name="ir_intensity_front_center_left">
        <ros>
          <namespace></namespace>
          <remapping>~/out:=_internal/ir_intensity_front_center_left</remapping>
        </ros>
      </plugin>
    </sensor>
  </gazebo>
  <joint name="ir_intensity_front_center_right_joint" type="fixed">
    <origin rpy="0 0 -0.436" xyz="0.1396 -0.0651 0.05720000000000001"/>
    <parent link="base_link"/>
    <child link="ir_intensity_front_center_right"/>
  </joint>
  <link name="ir_intensity_front_center_right">
    <inertial>
      <mass value="0.01"/>
      <origin xyz="0 0 0"/>
      <inertia ixx="1.6666666666666668e-07" ixy="0.0" ixz="0.0" iyy="1.6666666666666668e-07" iyz="0.0" izz="1.6666666666666668e-07"/>
    </inertial>
  </link>
  <gazebo reference="ir_intensity_front_center_right_joint">
    <preserveFixedJoint>true</preserveFixedJoint>
  </gazebo>
  <gazebo reference="ir_intensity_front_center_right">
    <sensor name="ir_intensity_front_center_right" type="ray">
      <update_rate>62.0</update_rate>
      <visualize>False</visualize>
      <always_on>true</always_on>
      <ray>
        <scan>
          <horizontal>
            <samples>5</samples>
            <resolution>1.0</resolution>
            <min_angle>-0.08726646259971647</min_angle>
            <max_angle>0.08726646259971647</max_angle>
          </horizontal>
          <vertical>
            <samples>5</samples>
            <resolution>1.0</resolution>
            <min_angle>-0.08726646259971647</min_angle>
            <max_angle>0.08726646259971647</max_angle>
          </vertical>
        </scan>
        <range>
          <min>0.025</min>
          <max>0.2</max>
          <resolution>1.0</resolution>
        </range>
      </ray>
      <!-- Noise is currently disabled -->
      <noise>
        <type>gaussian</type>
        <mean>0.0</mean>
        <stddev>0.0</stddev>
      </noise>
      <plugin filename="libgazebo_ros_create_ir_intensity_sensor.so" name="ir_intensity_front_center_right">
        <ros>
          <namespace></namespace>
          <remapping>~/out:=_internal/ir_intensity_front_center_right</remapping>
        </ros>
      </plugin>
    </sensor>
  </gazebo>
  <joint name="ir_intensity_front_left_joint" type="fixed">
    <origin rpy="0 0 0.436" xyz="0.1396 0.0651 0.05720000000000001"/>
    <parent link="base_link"/>
    <child link="ir_intensity_front_left"/>
  </joint>
  <link name="ir_intensity_front_left">
    <inertial>
      <mass value="0.01"/>
      <origin xyz="0 0 0"/>
      <inertia ixx="1.6666666666666668e-07" ixy="0.0" ixz="0.0" iyy="1.6666666666666668e-07" iyz="0.0" izz="1.6666666666666668e-07"/>
    </inertial>
  </link>
  <gazebo reference="ir_intensity_front_left_joint">
    <preserveFixedJoint>true</preserveFixedJoint>
  </gazebo>
  <gazebo reference="ir_intensity_front_left">
    <sensor name="ir_intensity_front_left" type="ray">
      <update_rate>62.0</update_rate>
      <visualize>False</visualize>
      <always_on>true</always_on>
      <ray>
        <scan>
          <horizontal>
            <samples>5</samples>
            <resolution>1.0</resolution>
            <min_angle>-0.08726646259971647</min_angle>
            <max_angle>0.08726646259971647</max_angle>
          </horizontal>
          <vertical>
            <samples>5</samples>
            <resolution>1.0</resolution>
            <min_angle>-0.08726646259971647</min_angle>
            <max_angle>0.08726646259971647</max_angle>
          </vertical>
        </scan>
        <range>
          <min>0.025</min>
          <max>0.2</max>
          <resolution>1.0</resolution>
        </range>
      </ray>
      <!-- Noise is currently disabled -->
      <noise>
        <type>gaussian</type>
        <mean>0.0</mean>
        <stddev>0.0</stddev>
      </noise>
      <plugin filename="libgazebo_ros_create_ir_intensity_sensor.so" name="ir_intensity_front_left">
        <ros>
          <namespace></namespace>
          <remapping>~/out:=_internal/ir_intensity_front_left</remapping>
        </ros>
      </plugin>
    </sensor>
  </gazebo>
  <joint name="ir_intensity_front_right_joint" type="fixed">
    <origin rpy="0 0 -0.873" xyz="0.0990 -0.1180 0.05720000000000001"/>
    <parent link="base_link"/>
    <child link="ir_intensity_front_right"/>
  </joint>
  <link name="ir_intensity_front_right">
    <inertial>
      <mass value="0.01"/>
      <origin xyz="0 0 0"/>
      <inertia ixx="1.6666666666666668e-07" ixy="0.0" ixz="0.0" iyy="1.6666666666666668e-07" iyz="0.0" izz="1.6666666666666668e-07"/>
    </inertial>
  </link>
  <gazebo reference="ir_intensity_front_right_joint">
    <preserveFixedJoint>true</preserveFixedJoint>
  </gazebo>
  <gazebo reference="ir_intensity_front_right">
    <sensor name="ir_intensity_front_right" type="ray">
      <update_rate>62.0</update_rate>
      <visualize>False</visualize>
      <always_on>true</always_on>
      <ray>
        <scan>
          <horizontal>
            <samples>5</samples>
            <resolution>1.0</resolution>
            <min_angle>-0.08726646259971647</min_angle>
            <max_angle>0.08726646259971647</max_angle>
          </horizontal>
          <vertical>
            <samples>5</samples>
            <resolution>1.0</resolution>
            <min_angle>-0.08726646259971647</min_angle>
            <max_angle>0.08726646259971647</max_angle>
          </vertical>
        </scan>
        <range>
          <min>0.025</min>
          <max>0.2</max>
          <resolution>1.0</resolution>
        </range>
      </ray>
      <!-- Noise is currently disabled -->
      <noise>
        <type>gaussian</type>
        <mean>0.0</mean>
        <stddev>0.0</stddev>
      </noise>
      <plugin filename="libgazebo_ros_create_ir_intensity_sensor.so" name="ir_intensity_front_right">
        <ros>
          <namespace></namespace>
          <remapping>~/out:=_internal/ir_intensity_front_right</remapping>
        </ros>
      </plugin>
    </sensor>
  </gazebo>
  <joint name="ir_intensity_left_joint" type="fixed">
    <origin rpy="0 0 0.873" xyz="0.0990 0.1180 0.05720000000000001"/>
    <parent link="base_link"/>
    <child link="ir_intensity_left"/>
  </joint>
  <link name="ir_intensity_left">
    <inertial>
      <mass value="0.01"/>
      <origin xyz="0 0 0"/>
      <inertia ixx="1.6666666666666668e-07" ixy="0.0" ixz="0.0" iyy="1.6666666666666668e-07" iyz="0.0" izz="1.6666666666666668e-07"/>
    </inertial>
  </link>
  <gazebo reference="ir_intensity_left_joint">
    <preserveFixedJoint>true</preserveFixedJoint>
  </gazebo>
  <gazebo reference="ir_intensity_left">
    <sensor name="ir_intensity_left" type="ray">
      <update_rate>62.0</update_rate>
      <visualize>False</visualize>
      <always_on>true</always_on>
      <ray>
        <scan>
          <horizontal>
            <samples>5</samples>
            <resolution>1.0</resolution>
            <min_angle>-0.08726646259971647</min_angle>
            <max_angle>0.08726646259971647</max_angle>
          </horizontal>
          <vertical>
            <samples>5</samples>
            <resolution>1.0</resolution>
            <min_angle>-0.08726646259971647</min_angle>
            <max_angle>0.08726646259971647</max_angle>
          </vertical>
        </scan>
        <range>
          <min>0.025</min>
          <max>0.2</max>
          <resolution>1.0</resolution>
        </range>
      </ray>
      <!-- Noise is currently disabled -->
      <noise>
        <type>gaussian</type>
        <mean>0.0</mean>
        <stddev>0.0</stddev>
      </noise>
      <plugin filename="libgazebo_ros_create_ir_intensity_sensor.so" name="ir_intensity_left">
        <ros>
          <namespace></namespace>
          <remapping>~/out:=_internal/ir_intensity_left</remapping>
        </ros>
      </plugin>
    </sensor>
  </gazebo>
  <joint name="ir_intensity_right_joint" type="fixed">
    <origin rpy="0 0 -1.309" xyz="0.0399 -0.1488 0.05720000000000001"/>
    <parent link="base_link"/>
    <child link="ir_intensity_right"/>
  </joint>
  <link name="ir_intensity_right">
    <inertial>
      <mass value="0.01"/>
      <origin xyz="0 0 0"/>
      <inertia ixx="1.6666666666666668e-07" ixy="0.0" ixz="0.0" iyy="1.6666666666666668e-07" iyz="0.0" izz="1.6666666666666668e-07"/>
    </inertial>
  </link>
  <gazebo reference="ir_intensity_right_joint">
    <preserveFixedJoint>true</preserveFixedJoint>
  </gazebo>
  <gazebo reference="ir_intensity_right">
    <sensor name="ir_intensity_right" type="ray">
      <update_rate>62.0</update_rate>
      <visualize>False</visualize>
      <always_on>true</always_on>
      <ray>
        <scan>
          <horizontal>
            <samples>5</samples>
            <resolution>1.0</resolution>
            <min_angle>-0.08726646259971647</min_angle>
            <max_angle>0.08726646259971647</max_angle>
          </horizontal>
          <vertical>
            <samples>5</samples>
            <resolution>1.0</resolution>
            <min_angle>-0.08726646259971647</min_angle>
            <max_angle>0.08726646259971647</max_angle>
          </vertical>
        </scan>
        <range>
          <min>0.025</min>
          <max>0.2</max>
          <resolution>1.0</resolution>
        </range>
      </ray>
      <!-- Noise is currently disabled -->
      <noise>
        <type>gaussian</type>
        <mean>0.0</mean>
        <stddev>0.0</stddev>
      </noise>
      <plugin filename="libgazebo_ros_create_ir_intensity_sensor.so" name="ir_intensity_right">
        <ros>
          <namespace></namespace>
          <remapping>~/out:=_internal/ir_intensity_right</remapping>
        </ros>
      </plugin>
    </sensor>
  </gazebo>
  <joint name="ir_intensity_side_left_joint" type="fixed">
    <origin rpy="0 0 1.309" xyz="0.0399 0.1488 0.05720000000000001"/>
    <parent link="base_link"/>
    <child link="ir_intensity_side_left"/>
  </joint>
  <link name="ir_intensity_side_left">
    <inertial>
      <mass value="0.01"/>
      <origin xyz="0 0 0"/>
      <inertia ixx="1.6666666666666668e-07" ixy="0.0" ixz="0.0" iyy="1.6666666666666668e-07" iyz="0.0" izz="1.6666666666666668e-07"/>
    </inertial>
  </link>
  <gazebo reference="ir_intensity_side_left_joint">
    <preserveFixedJoint>true</preserveFixedJoint>
  </gazebo>
  <gazebo reference="ir_intensity_side_left">
    <sensor name="ir_intensity_side_left" type="ray">
      <update_rate>62.0</update_rate>
      <visualize>False</visualize>
      <always_on>true</always_on>
      <ray>
        <scan>
          <horizontal>
            <samples>5</samples>
            <resolution>1.0</resolution>
            <min_angle>-0.08726646259971647</min_angle>
            <max_angle>0.08726646259971647</max_angle>
          </horizontal>
          <vertical>
            <samples>5</samples>
            <resolution>1.0</resolution>
            <min_angle>-0.08726646259971647</min_angle>
            <max_angle>0.08726646259971647</max_angle>
          </vertical>
        </scan>
        <range>
          <min>0.025</min>
          <max>0.2</max>
          <resolution>1.0</resolution>
        </range>
      </ray>
      <!-- Noise is currently disabled -->
      <noise>
        <type>gaussian</type>
        <mean>0.0</mean>
        <stddev>0.0</stddev>
      </noise>
      <plugin filename="libgazebo_ros_create_ir_intensity_sensor.so" name="ir_intensity_side_left">
        <ros>
          <namespace></namespace>
          <remapping>~/out:=_internal/ir_intensity_side_left</remapping>
        </ros>
      </plugin>
    </sensor>
  </gazebo>
  <joint name="button_1_joint" type="fixed">
    <parent link="base_link"/>
    <child link="button_1"/>
    <origin rpy="0 -1.5707963267948966 0" xyz="0.06 0.37 0.1442"/>
  </joint>
  <link name="button_1"/>
  <joint name="button_2_joint" type="fixed">
    <parent link="base_link"/>
    <child link="button_2"/>
    <origin rpy="0 -1.5707963267948966 0" xyz="0.06 -0.37 0.1442"/>
  </joint>
  <link name="button_2"/>
  <joint name="button_power_joint" type="fixed">
    <parent link="base_link"/>
    <child link="button_power"/>
    <origin rpy="0 -1.5707963267948966 0" xyz="0.06 0 0.1442"/>
  </joint>
  <link name="button_power"/>
  <joint name="ir_omni_joint" type="fixed">
    <origin xyz="0.153 0 0.09920000000000001"/>
    <parent link="base_link"/>
    <child link="ir_omni"/>
  </joint>
  <link name="ir_omni">
    <inertial>
      <mass value="0.01"/>
      <origin xyz="0 0 0"/>
      <inertia ixx="1.6666666666666668e-07" ixy="0.0" ixz="0.0" iyy="1.6666666666666668e-07" iyz="0.0" izz="1.6666666666666668e-07"/>
    </inertial>
  </link>
  <gazebo>
    <plugin filename="libgazebo_ros_create_ir_opcode.so" name="ir_omni_plugin">
      <ros>
        <namespace></namespace>
        <remapping>~/out:=ir_opcode</remapping>
      </ros>
      <update_rate>62</update_rate>
      <robot_model_name>create3</robot_model_name>
      <receiver_link_name>ir_omni</receiver_link_name>
      <dock_model_name>standard_dock</dock_model_name>
      <emitter_link_name>halo_link</emitter_link_name>
      <sensor_0_fov>3.839724354387525</sensor_0_fov>
      <sensor_0_range>0.01</sensor_0_range>
      <sensor_1_fov>1.5707963267948966</sensor_1_fov>
      <sensor_1_range>0.5</sensor_1_range>
    </plugin>
  </gazebo>
  <gazebo reference="ir_omni_joint">
    <preserveFixedJoint>true</preserveFixedJoint>
  </gazebo>
  <!-- Ground truth pose -->
  <gazebo>
    <plugin filename="libgazebo_ros_p3d.so" name="gazebo_ros_p3d_robot">
      <ros>
        <namespace></namespace>
        <remapping>odom:=sim_ground_truth_pose</remapping>
      </ros>
      <body_name>base_link</body_name>
      <frame_name>world</frame_name>
      <update_rate>62</update_rate>
      <xyz_offset>0 0 0</xyz_offset>
      <rpy_offset>0.0 0.0 0.0</rpy_offset>
      <gaussian_noise>0.0</gaussian_noise>
    </plugin>
  </gazebo>
  <!-- Dock status -->
  <gazebo>
    <plugin filename="libgazebo_ros_create_docking_status.so" name="dock_status_publisher">
      <ros>
        <namespace></namespace>
        <remapping>~/out:=dock_status</remapping>
      </ros>
      <update_rate>1.0</update_rate>
      <robot_model_name>create3</robot_model_name>
      <receiver_link_name>ir_omni</receiver_link_name>
      <dock_model_name>standard_dock</dock_model_name>
      <emitter_link_name>halo_link</emitter_link_name>
    </plugin>
  </gazebo>
  <material name="interbotix_black">
    <texture filename="package://interbotix_xsarm_descriptions/meshes/interbotix_black.png"/>
  </material>
  <!-- use_world_frame -->
  <link name="wx200/base_link">
    <visual>
      <origin rpy="0 0 1.5707963267948966" xyz="0 0 0"/>
      <geometry>
        <mesh filename="package://interbotix_xsarm_descriptions/meshes/wx200_meshes/base.stl" scale="0.001 0.001 0.001"/>
      </geometry>
      <material name="interbotix_black"/>
    </visual>
    <collision>
      <origin rpy="0 0 1.5707963267948966" xyz="0 0 0"/>
      <geometry>
        <mesh filename="package://interbotix_xsarm_descriptions/meshes/wx200_meshes/base.stl" scale="0.001 0.001 0.001"/>
      </geometry>
    </collision>
    <inertial>
      <origin rpy="0 0 1.5707963267948966" xyz="-0.0381747000 0.0006478630 0.0193458000"/>
      <mass value="0.540142"/>
      <inertia ixx="0.0021190000" ixy="-0.0000172100" ixz="0.0000006389" iyy="0.0006925000" iyz="0.0000461200" izz="0.0025280000"/>
    </inertial>
  </link>
  <joint name="waist" type="revolute">
    <axis xyz="0 0 1"/>
    <limit effort="8" lower="-3.141582653589793" upper="3.141582653589793" velocity="3.141592653589793"/>
    <origin rpy="0 0 0" xyz="0 0 0.072"/>
    <parent link="wx200/base_link"/>
    <child link="wx200/shoulder_link"/>
    <dynamics damping="0.1" friction="0.1"/>
  </joint>
  <link name="wx200/shoulder_link">
    <visual>
      <origin rpy="0 0 1.5707963267948966" xyz="0 0 -0.003"/>
      <geometry>
        <mesh filename="package://interbotix_xsarm_descriptions/meshes/wx200_meshes/shoulder.stl" scale="0.001 0.001 0.001"/>
      </geometry>
      <material name="interbotix_black"/>
    </visual>
    <collision>
      <origin rpy="0 0 1.5707963267948966" xyz="0 0 -0.003"/>
      <geometry>
        <mesh filename="package://interbotix_xsarm_descriptions/meshes/wx200_meshes/shoulder.stl" scale="0.001 0.001 0.001"/>
      </geometry>
    </collision>
    <inertial>
      <origin rpy="0 0 1.5707963267948966" xyz="0.0000223210 0.0000414608 0.0066287000"/>
      <mass value="0.480879"/>
      <inertia ixx="0.0003790000" ixy="0.0000000022" ixz="-0.0000003561" iyy="0.0005557000" iyz="0.0000012247" izz="0.0005889000"/>
    </inertial>
  </link>
  <joint name="shoulder" type="revolute">
    <axis xyz="0 1 0"/>
    <limit effort="18" lower="-1.8849555921538759" upper="1.9722220547535925" velocity="1"/>
    <origin rpy="0 0 0" xyz="0 0 0.03865"/>
    <parent link="wx200/shoulder_link"/>
    <child link="wx200/upper_arm_link"/>
    <dynamics damping="0.1" friction="0.1"/>
  </joint>
  <link name="wx200/upper_arm_link">
    <visual>
      <origin rpy="0 0 1.5707963267948966" xyz="0 0 0"/>
      <geometry>
        <mesh filename="package://interbotix_xsarm_descriptions/meshes/wx200_meshes/upper_arm.stl" scale="0.001 0.001 0.001"/>
      </geometry>
      <material name="interbotix_black"/>
    </visual>
    <collision>
      <origin rpy="0 0 1.5707963267948966" xyz="0 0 0"/>
      <geometry>
        <mesh filename="package://interbotix_xsarm_descriptions/meshes/wx200_meshes/upper_arm.stl" scale="0.001 0.001 0.001"/>
      </geometry>
    </collision>
    <inertial>
      <origin rpy="0 0 1.5707963267948966" xyz="0.0119707000 -0.0001179264 0.1394290000"/>
      <mass value="0.297781"/>
      <inertia ixx="0.0017100000" ixy="-0.0000011433" ixz="0.0000021161" iyy="0.0016310000" iyz="0.0002135000" izz="0.0001482000"/>
    </inertial>
  </link>
  <joint name="elbow" type="revolute">
    <axis xyz="0 1 0"/>
    <limit effort="13" lower="-1.8849555921538759" upper="1.6231562043547265" velocity="3.141592653589793"/>
    <origin rpy="0 0 0" xyz="0.05 0 0.2"/>
    <parent link="wx200/upper_arm_link"/>
    <child link="wx200/forearm_link"/>
    <dynamics damping="0.1" friction="0.1"/>
  </joint>
  <link name="wx200/forearm_link">
    <visual>
      <origin rpy="0 0 1.5707963267948966" xyz="0 0 0"/>
      <geometry>
        <mesh filename="package://interbotix_xsarm_descriptions/meshes/wx200_meshes/forearm.stl" scale="0.001 0.001 0.001"/>
      </geometry>
      <material name="interbotix_black"/>
    </visual>
    <collision>
      <origin rpy="0 0 1.5707963267948966" xyz="0 0 0"/>
      <geometry>
        <mesh filename="package://interbotix_xsarm_descriptions/meshes/wx200_meshes/forearm.stl" scale="0.001 0.001 0.001"/>
      </geometry>
    </collision>
    <inertial>
      <origin rpy="0 0 1.5707963267948966" xyz="0.1211920000 -0.0001238123 0.0000000000"/>
      <mass value="0.283651"/>
      <inertia ixx="0.0011850000" ixy="-0.0000024317" ixz="0.0000000000" iyy="0.0000682900" iyz="0.0000000000" izz="0.0012060000"/>
    </inertial>
  </link>
  <joint name="wrist_angle" type="revolute">
    <axis xyz="0 1 0"/>
    <limit effort="5" lower="-1.7453292519943295" upper="2.1467549799530254" velocity="3.141592653589793"/>
    <origin rpy="0 0 0" xyz="0.2 0 0"/>
    <parent link="wx200/forearm_link"/>
    <child link="wx200/wrist_link"/>
    <dynamics damping="0.1" friction="0.1"/>
  </joint>
  <link name="wx200/wrist_link">
    <visual>
      <origin rpy="0 0 1.5707963267948966" xyz="0 0 0"/>
      <geometry>
        <mesh filename="package://interbotix_xsarm_descriptions/meshes/wx200_meshes/wrist.stl" scale="0.001 0.001 0.001"/>
      </geometry>
      <material name="interbotix_black"/>
    </visual>
    <collision>
      <origin rpy="0 0 1.5707963267948966" xyz="0 0 0"/>
      <geometry>
        <mesh filename="package://interbotix_xsarm_descriptions/meshes/wx200_meshes/wrist.stl" scale="0.001 0.001 0.001"/>
      </geometry>
    </collision>
    <inertial>
      <origin rpy="0 0 1.5707963267948966" xyz="0.0423600000 -0.0000106630 0.0105770000"/>
      <mass value="0.084957"/>
      <inertia ixx="0.0000308200" ixy="0.0000000191" ixz="0.0000000023" iyy="0.0000282200" iyz="0.0000025481" izz="0.0000315200"/>
    </inertial>
  </link>
  <!-- Include the gripper if used -->
  <joint name="wrist_rotate" type="revolute">
    <axis xyz="1 0 0"/>
    <limit effort="1" lower="-3.141582653589793" upper="3.141582653589793" velocity="3.141592653589793"/>
    <origin rpy="0 0 0" xyz="0.065 0 0"/>
    <parent link="wx200/wrist_link"/>
    <child link="wx200/gripper_link"/>
    <dynamics damping="0.1" friction="0.1"/>
  </joint>
  <link name="wx200/gripper_link">
    <visual>
      <origin rpy="0 0 1.5707963267948966" xyz="-0.02 0 0"/>
      <geometry>
        <mesh filename="package://interbotix_xsarm_descriptions/meshes/wx200_meshes/gripper.stl" scale="0.001 0.001 0.001"/>
      </geometry>
      <material name="interbotix_black"/>
    </visual>
    <collision>
      <origin rpy="0 0 1.5707963267948966" xyz="-0.02 0 0"/>
      <geometry>
        <mesh filename="package://interbotix_xsarm_descriptions/meshes/wx200_meshes/gripper.stl" scale="0.001 0.001 0.001"/>
      </geometry>
    </collision>
    <inertial>
      <origin rpy="0 0 1.5707963267948966" xyz="0.0216310000 0.0000002516 0.0114100000"/>
      <mass value="0.072885"/>
      <inertia ixx="0.0000253700" ixy="0.0000000000" ixz="0.0000000000" iyy="0.0000183600" iyz="0.0000004340" izz="0.0000167400"/>
    </inertial>
  </link>
  <joint name="ee_arm" type="fixed">
    <axis xyz="1 0 0"/>
    <origin rpy="0 0 0" xyz="0.043 0 0"/>
    <parent link="wx200/gripper_link"/>
    <child link="wx200/ee_arm_link"/>
  </joint>
  <link name="wx200/ee_arm_link">
    <inertial>
      <mass value="0.001"/>
      <inertia ixx="0.001" ixy="0" ixz="0" iyy="0.001" iyz="0" izz="0.001"/>
    </inertial>
  </link>
  <joint name="gripper" type="continuous">
    <axis xyz="1 0 0"/>
    <limit effort="1" velocity="3.141592653589793"/>
    <origin rpy="0 0 0" xyz="0.0055 0 0"/>
    <parent link="wx200/ee_arm_link"/>
    <child link="wx200/gripper_prop_link"/>
    <dynamics damping="0.1" friction="0.1"/>
  </joint>
  <link name="wx200/gripper_prop_link">
    <visual>
      <origin rpy="0 0 1.5707963267948966" xyz="-0.0685 0 0"/>
      <geometry>
        <mesh filename="package://interbotix_xsarm_descriptions/meshes/wx200_meshes/gripper_prop.stl" scale="0.001 0.001 0.001"/>
      </geometry>
      <material name="interbotix_black"/>
    </visual>
    <collision>
      <origin rpy="0 0 1.5707963267948966" xyz="-0.0685 0 0"/>
      <geometry>
        <mesh filename="package://interbotix_xsarm_descriptions/meshes/wx200_meshes/gripper_prop.stl" scale="0.001 0.001 0.001"/>
      </geometry>
    </collision>
    <inertial>
      <origin rpy="0 0 1.5707963267948966" xyz="0.0008460000 -0.0000016817 0.0000420000"/>
      <mass value="0.00434"/>
      <inertia ixx="0.0000005923" ixy="0.0000000000" ixz="0.0000003195" iyy="0.0000011156" iyz="-0.0000000004" izz="0.0000005743"/>
    </inertial>
  </link>
  <!-- If the AR tag is being used, then add the AR tag mount -->
  <!-- show_ar_tag -->
  <!-- If the gripper bar is being used, then also add the gripper bar -->
  <joint name="gripper_bar" type="fixed">
    <axis xyz="1 0 0"/>
    <origin rpy="0 0 0" xyz="0 0 0"/>
    <parent link="wx200/ee_arm_link"/>
    <child link="wx200/gripper_bar_link"/>
  </joint>
  <link name="wx200/gripper_bar_link">
    <visual>
      <origin rpy="0 0 1.5707963267948966" xyz="-0.063 0 0"/>
      <geometry>
        <mesh filename="package://interbotix_xsarm_descriptions/meshes/wx200_meshes/gripper_bar.stl" scale="0.001 0.001 0.001"/>
      </geometry>
      <material name="interbotix_black"/>
    </visual>
    <collision>
      <origin rpy="0 0 1.5707963267948966" xyz="-0.063 0 0"/>
      <geometry>
        <mesh filename="package://interbotix_xsarm_descriptions/meshes/wx200_meshes/gripper_bar.stl" scale="0.001 0.001 0.001"/>
      </geometry>
    </collision>
    <inertial>
      <origin rpy="0 0 1.5707963267948966" xyz="0.0096870000 0.0000008177 0.0049620000"/>
      <mass value="0.034199"/>
      <inertia ixx="0.0000074125" ixy="-0.0000000008" ixz="-0.0000000006" iyy="0.0000284300" iyz="-0.0000013889" izz="0.0000286000"/>
    </inertial>
  </link>
  <joint name="ee_bar" type="fixed">
    <axis xyz="1 0 0"/>
    <origin rpy="0 0 0" xyz="0.023 0 0"/>
    <parent link="wx200/gripper_bar_link"/>
    <child link="wx200/fingers_link"/>
  </joint>
  <link name="wx200/fingers_link">
    <inertial>
      <mass value="0.001"/>
      <inertia ixx="0.001" ixy="0" ixz="0" iyy="0.001" iyz="0" izz="0.001"/>
    </inertial>
  </link>
  <!-- If the gripper fingers are being used, add those as well -->
  <joint name="left_finger" type="prismatic">
    <axis xyz="0 1 0"/>
    <limit effort="5" lower="0.015" upper="0.037" velocity="1"/>
    <origin rpy="0 0 0" xyz="0 0 0"/>
    <parent link="wx200/fingers_link"/>
    <child link="wx200/left_finger_link"/>
    <dynamics damping="0.1" friction="0.1"/>
  </joint>
  <link name="wx200/left_finger_link">
    <visual>
      <origin rpy="3.141592653589793 3.141592653589793 0" xyz="0 0.005 0"/>
      <geometry>
        <mesh filename="package://interbotix_xsarm_descriptions/meshes/wx200_meshes/gripper_finger.stl" scale="0.001 0.001 0.001"/>
      </geometry>
      <material name="interbotix_black"/>
    </visual>
    <collision>
      <origin rpy="3.141592653589793 3.141592653589793 0" xyz="0 0.005 0"/>
      <geometry>
        <mesh filename="package://interbotix_xsarm_descriptions/meshes/wx200_meshes/gripper_finger.stl" scale="0.001 0.001 0.001"/>
      </geometry>
    </collision>
    <inertial>
      <origin rpy="3.141592653589793 3.141592653589793 1.5707963267948966" xyz="0.0138160000 0.0000000000 0.0000000000"/>
      <mass value="0.016246"/>
      <inertia ixx="0.0000047310" ixy="-0.0000004560" ixz="0.0000000000" iyy="0.0000015506" iyz="0.0000000000" izz="0.0000037467"/>
    </inertial>
  </link>
  <joint name="right_finger" type="prismatic">
    <axis xyz="0 1 0"/>
    <limit effort="5" lower="-0.037" upper="-0.015" velocity="1"/>
    <origin rpy="0 0 0" xyz="0 0 0"/>
    <parent link="wx200/fingers_link"/>
    <child link="wx200/right_finger_link"/>
    <dynamics damping="0.1" friction="0.1"/>
    <mimic joint="left_finger" multiplier="-1" offset="0"/>
  </joint>
  <link name="wx200/right_finger_link">
    <visual>
      <origin rpy="0 3.141592653589793 0" xyz="0 -0.005 0"/>
      <geometry>
        <mesh filename="package://interbotix_xsarm_descriptions/meshes/wx200_meshes/gripper_finger.stl" scale="0.001 0.001 0.001"/>
      </geometry>
      <material name="interbotix_black"/>
    </visual>
    <collision>
      <origin rpy="0 3.141592653589793 0" xyz="0 -0.005 0"/>
      <geometry>
        <mesh filename="package://interbotix_xsarm_descriptions/meshes/wx200_meshes/gripper_finger.stl" scale="0.001 0.001 0.001"/>
      </geometry>
    </collision>
    <inertial>
      <origin rpy="0 3.141592653589793 1.5707963267948966" xyz="0.0138160000 0.0000000000  0.0000000000"/>
      <mass value="0.016246"/>
      <inertia ixx="0.0000047310" ixy="0.0000004560" ixz="0.0000000000" iyy="0.0000015506" iyz="0.0000000000" izz="0.0000037467"/>
    </inertial>
  </link>
  <joint name="ee_gripper" type="fixed">
    <axis xyz="1 0 0"/>
    <origin rpy="0 0 0" xyz="0.027575 0 0"/>
    <parent link="wx200/fingers_link"/>
    <child link="wx200/ee_gripper_link"/>
  </joint>
  <link name="wx200/ee_gripper_link">
    <inertial>
      <mass value="0.001"/>
      <inertia ixx="0.001" ixy="0" ixz="0" iyy="0.001" iyz="0" izz="0.001"/>
    </inertial>
  </link>
  <!-- show_gripper_fingers -->
  <!-- show_gripper_bar -->
  <!-- use_gripper -->
  <ros2_control name="XSHardwareInterface" type="system">
    <hardware>
      <plugin>interbotix_xs_ros_control/XSHardwareInterface</plugin>
      <param name="loop_hz">10</param>
      <param name="group_name">arm</param>
      <param name="gripper_name">gripper</param>
      <param name="joint_states_topic">joint_states</param>
    </hardware>
    <joint name="waist">
      <command_interface name="position">
        <param name="min">&quot;-3.141582653589793&quot;</param>
        <param name="max">&quot;3.141582653589793&quot;</param>
      </command_interface>
      <state_interface name="position"/>
    </joint>
    <joint name="shoulder">
      <command_interface name="position">
        <param name="min">&quot;-1.8849555921538759&quot;</param>
        <param name="max">&quot;1.9722220547535925&quot;</param>
      </command_interface>
      <state_interface name="position"/>
    </joint>
    <joint name="elbow">
      <command_interface name="position">
        <param name="min">&quot;-1.8849555921538759&quot;</param>
        <param name="max">&quot;1.6231562043547265&quot;</param>
      </command_interface>
      <state_interface name="position"/>
    </joint>
    <joint name="wrist_angle">
      <command_interface name="position">
        <param name="min">&quot;-1.7453292519943295&quot;</param>
        <param name="max">&quot;2.1467549799530254&quot;</param>
      </command_interface>
      <state_interface name="position"/>
    </joint>
    <joint name="wrist_rotate">
      <command_interface name="position">
        <param name="min">&quot;-3.141582653589793&quot;</param>
        <param name="max">&quot;3.141582653589793&quot;</param>
      </command_interface>
      <state_interface name="position"/>
    </joint>
    <joint name="left_finger">
      <command_interface name="position">
        <param name="min">&quot;0.015&quot;</param>
        <param name="max">&quot;-0.015&quot;</param>
      </command_interface>
      <state_interface name="position"/>
    </joint>
  </ros2_control>
  <material name="camera_aluminum">
    <color rgba="0.5 0.5 0.5 1"/>
  </material>
  <!-- camera body, with origin at bottom screw mount -->
  <joint name="camera_joint" type="fixed">
    <origin rpy="0 0 0" xyz="0 0 0"/>
    <parent link="base_link"/>
    <child link="camera_bottom_screw_frame"/>
  </joint>
  <link name="camera_bottom_screw_frame"/>
  <joint name="camera_link_joint" type="fixed">
    <origin rpy="0 0 0" xyz="0 0.0175 0.0125"/>
    <parent link="camera_bottom_screw_frame"/>
    <child link="camera_link"/>
  </joint>
  <link name="camera_link">
    <visual>
      <origin rpy="1.5707963267948966 0 1.5707963267948966" xyz="0.0149 -0.0175 0"/>
      <geometry>
        <!-- <box size="${d435_cam_width} ${d435_cam_height} ${d435_cam_depth}"/> -->
        <mesh filename="package://realsense2_description/meshes/d435.dae"/>
        <!--<mesh filename="package://realsense2_description/meshes/d435/d435.dae" />-->
      </geometry>
      <material name="camera_aluminum"/>
    </visual>
    <collision>
      <origin rpy="0 0 0" xyz="0 -0.0175 0"/>
      <geometry>
        <box size="0.02505 0.09 0.025"/>
      </geometry>
    </collision>
    <inertial>
      <!-- The following are not reliable values, and should not be used for modeling -->
      <mass value="0.564"/>
      <origin xyz="0 0 0"/>
      <inertia ixx="0.003881243" ixy="0.0" ixz="0.0" iyy="0.000498940" iyz="0.0" izz="0.003879257"/>
    </inertial>
  </link>
  <!-- camera depth joints and links -->
  <joint name="camera_depth_joint" type="fixed">
    <origin rpy="0 0 0" xyz="0 0 0"/>
    <parent link="camera_link"/>
    <child link="camera_depth_frame"/>
  </joint>
  <link name="camera_depth_frame"/>
  <joint name="camera_depth_optical_joint" type="fixed">
    <origin rpy="-1.5707963267948966 0 -1.5707963267948966" xyz="0 0 0"/>
    <parent link="camera_depth_frame"/>
    <child link="camera_depth_optical_frame"/>
  </joint>
  <link name="camera_depth_optical_frame"/>
  <!-- camera left IR joints and links -->
  <joint name="camera_left_ir_joint" type="fixed">
    <origin rpy="0 0 0" xyz="0 0.0 0"/>
    <parent link="camera_depth_frame"/>
    <child link="camera_left_ir_frame"/>
  </joint>
  <link name="camera_left_ir_frame"/>
  <joint name="camera_left_ir_optical_joint" type="fixed">
    <origin rpy="-1.5707963267948966 0 -1.5707963267948966" xyz="0 0 0"/>
    <parent link="camera_left_ir_frame"/>
    <child link="camera_left_ir_optical_frame"/>
  </joint>
  <link name="camera_left_ir_optical_frame"/>
  <!-- camera right IR joints and links -->
  <joint name="camera_right_ir_joint" type="fixed">
    <origin rpy="0 0 0" xyz="0 -0.05 0"/>
    <parent link="camera_depth_frame"/>
    <child link="camera_right_ir_frame"/>
  </joint>
  <link name="camera_right_ir_frame"/>
  <joint name="camera_right_ir_optical_joint" type="fixed">
    <origin rpy="-1.5707963267948966 0 -1.5707963267948966" xyz="0 0 0"/>
    <parent link="camera_right_ir_frame"/>
    <child link="camera_right_ir_optical_frame"/>
  </joint>
  <link name="camera_right_ir_optical_frame"/>
  <!-- camera color joints and links -->
  <joint name="camera_color_joint" type="fixed">
    <origin rpy="0 0 0" xyz="0 0.015 0"/>
    <parent link="camera_depth_frame"/>
    <child link="camera_color_frame"/>
  </joint>
  <link name="camera_color_frame"/>
  <joint name="camera_color_optical_joint" type="fixed">
    <origin rpy="-1.5707963267948966 0 -1.5707963267948966" xyz="0 0 0"/>
    <parent link="camera_color_frame"/>
    <child link="camera_color_optical_frame"/>
  </joint>
  <link name="camera_color_optical_frame"/>
  <link name="laser_link">
    <visual>
      <origin rpy="0 0 0" xyz="0 0 0"/>
      <geometry>
        <cylinder length="0.02" radius="0.02"/>
      </geometry>
      <material name="black">
        <color rgba="0.0 0.0 0.0 0.8"/>
      </material>
    </visual>
  </link>
  <joint name="laser_joint" type="fixed">
    <parent link="base_link"/>
    <child link="laser_link"/>
    <origin xyz="0 0 0.275"/>
  </joint>
  <joint name="arm_joint" type="fixed">
    <parent link="base_link"/>
    <child link="wx200/base_link"/>
    <origin xyz="0 0 0.275"/>
  </joint>
</robot>
